Workbook
Name Graph_Down: 'A Florent'!#REF!
Name Graph_Down: Dansler!#REF!
Name Graph_Down: doug!#REF!
Name Graph_Down: 'Emmanuel D'!#REF!
Name Graph_Down: 'Joris R'!#REF!
Name Graph_Down: Lesnoff!#REF!
Name Graph_Down: Lijour!#REF!
Name Graph_Down: 'Loudiyi '!#REF!
Name Graph_Down: mark!#REF!
Name Graph_Down: OPEX!#REF!
Name Graph_Down: pierre!#REF!
Name Graph_Down: Roger!#REF!
Name Graph_Down: #REF!
Name TableRes: 'A Florent'!$B$5
Name TableRes: Dansler!$B$5
Name TableRes: doug!$B$5
Name TableRes: 'Emmanuel D'!$B$5
Name TableRes: 'Joris R'!$B$5
Name TableRes: Lesnoff!$B$5
Name TableRes: Lijour!$B$5
Name TableRes: 'Loudiyi '!$B$5
Name TableRes: mark!$B$5
Name TableRes: OPEX!$B$5
Name TableRes: pierre!$B$5
Name TableRes: Roger!$B$5
Name TableRes: #REF!
Name VET: #REF!
Name VET: #REF!
Name VET: #REF!
Name VET: #REF!
Name VET: #REF!
Name VET: #REF!
Name VET: #REF!
Name VET: #REF!
Name VET: #REF!
Name VET: #REF!
Name VET: #REF!
Name VET: #REF!
Name VET: #REF!
Name X: OFFSET('A Florent'!#REF!,0,0,'A Florent'!$X$59,0)
Name X: OFFSET(Dansler!#REF!,0,0,Dansler!$X$59,0)
Name X: OFFSET(doug!#REF!,0,0,doug!$X$59,0)
Name X: OFFSET('Emmanuel D'!#REF!,0,0,'Emmanuel D'!$X$59,0)
Name X: OFFSET('Joris R'!#REF!,0,0,'Joris R'!$X$59,0)
Name X: OFFSET(Lesnoff!#REF!,0,0,Lesnoff!$X$59,0)
Name X: OFFSET(Lijour!#REF!,0,0,Lijour!$X$59,0)
Name X: OFFSET('Loudiyi '!#REF!,0,0,'Loudiyi '!$X$59,0)
Name X: OFFSET(mark!#REF!,0,0,mark!$X$59,0)
Name X: OFFSET(OPEX!#REF!,0,0,OPEX!$X$59,0)
Name X: OFFSET(pierre!#REF!,0,0,pierre!$X$59,0)
Name X: OFFSET(Roger!#REF!,0,0,Roger!$X$59,0)
Name X: OFFSET(#REF!,0,0,#REF!,0)
Name ZERO_REMOVED: 'A Florent'!#REF!
Name ZERO_REMOVED: Dansler!#REF!
Name ZERO_REMOVED: doug!#REF!
Name ZERO_REMOVED: 'Emmanuel D'!#REF!
Name ZERO_REMOVED: 'Joris R'!#REF!
Name ZERO_REMOVED: Lesnoff!#REF!
Name ZERO_REMOVED: Lijour!#REF!
Name ZERO_REMOVED: 'Loudiyi '!#REF!

Sheet Emmanuel D
W1: INSTRUCTIONS
C3: Challenge 2022 Emmanuel D.
C6: =CONCATENATE(D62," = f (",F62," )") -> REF = f (Ypred ) | H6: CALIBRATION INFORMATION
D7: =D62 -> REF | F7: =F62 -> Ypred | H7: N= | I7: 500 | X7: last point=
C8: N= | E8: =COUNT(Table2234210[REF]) -> 80 | H8: SECV= | I8: 1.2 | X8: =62+E8 -> 142
C9: Average= | D9: =AVERAGE(Table2234210[REF]) -> 11.1095 | F9: =AVERAGE(Table2234210[Ypred]) -> 10.952379 | H9: Number of Terms = | J9: 12
C10: Min= | D10: =MIN(Table2234210[REF]) -> 8.9700003 | E10: =ROUNDDOWN(MIN(D10,F10),0) -> 5 | F10: =MIN(Table2234210[Ypred]) -> 5.9089431 | H10: Alpha= | I10: 0.05 | W10: =E10+E20 -> 4.8428795
C11: Max= | D11: =MAX(Table2234210[REF]) -> 14.43 | E11: =ROUNDUP(MAX(D11,F11),0)+1 -> 18 | F11: =MAX(Table2234210[Ypred]) -> 16.442723 | H11: Tvalue= | I11: =TINV(I10,E8) -> 1.9900634 | W11: =E11+E20 -> 17.842879
C12: SD= | D12: =STDEV(Table2234210[REF]) -> 1.172905 | F12: =STDEV(Table2234210[Ypred]) -> 2.2888484 | H12: Fvalue= | I12: =FINV(I10,E8-1,I7-1-J9) -> 1.3057951
C13: Medians= | D13: =MEDIAN(Table2234210[REF]) -> 11.01 | F13: =MEDIAN(Table2234210[Ypred]) -> 10.995673
C14: SD_medians= | D14: =1.4826*(MEDIAN(Table2234210[abs(lab)])) -> 1.4677736 | F14: =1.4826*MEDIAN(Table2234210[abs(anl)]) -> 2.1065928
F15: Robust(medians)
C16: RMSEP= | E16: =SQRT(AVERAGE(Table2234210[dif^2])) -> 2.0264868 | F16: =SQRT(F18^2+E20^2) -> 2.7183607
C17: Median ABS errors= | F17: =MEDIAN(Table2234210[abs_errors]) -> 1.8304439
C18: SEPC= | E18: =STDEV(Table2234210[X-Y]) -> 2.0331336 | F18: =1.4826*MEDIAN(Table2234210[abs_errors]) -> 2.7138161 | H18: F_sep= | I18: =I8*I12 -> 1.5669542 | J18: =IF(E18>I18,"S"," ns ") -> S | X18: Yrec | Y18: Xrec
C19: RSDyx= | E19: =STEYX(Table2234210[REF],Table2234210[Ypred]) -> 1.0468351 | F19: =1.4826*MEDIAN(Table2234210[Abs_erroryx]) -> 1.0700527 | W19: y1rect= | X19: =E$26+E$25*E10 -> 8.0592431 | Y19: =E10 -> 5
C20: BIAS= | E20: =F9-D9 -> -0.15712055 | F20: =F13-D13 -> -0.014327692 | H20: Tobs_bias= | I20: =ABS(E20/(SQRT(SUM(Table2234210[dif^2])/(E8*(E8-1))))) -> 0.68913254 | J20: =IF(I20>I11,"S","ns") -> ns | W20: y2rect= | X20: =E$26+E$25*E11 -> 14.721006 | Y20: =E11 -> 18
C21: Slope= | E21: =SLOPE(Table2234210[REF],Table2234210[Ypred]) -> 0.23678018 | H21: Tobs_slope= | I21: =ABS(E21-1)*SQRT((E8-1)*F12^2/E19^2) -> 14.832076 | J21: =IF(I21>I11,"S"," ns ") -> S | W21: ym= | X21: =E$26+E$25*F9 -> 11.1095 | Y21: =F9 -> 10.952379
C22: Intercept= | E22: =INTERCEPT(Table2234210[REF],Table2234210[Ypred]) -> 8.5161936
C23: RSQ= | E23: =RSQ(Table2234210[REF],Table2234210[Ypred]) -> 0.2135006 | F23: =(D12^2-F19^2)/D12^2 -> 0.16769085
C24: RPD= | E24: =1/SQRT(1-E23) -> 1.1275889 | F24: =1/SQRT(1-F23) -> 1.0961189 | H24: RPD2= | I24: =D12/E19 -> 1.1204296
C25: Least rectangle slope= | E25: =(D12/F12) -> 0.51244329 | H25: Quartile75= | I25: =QUARTILE(Table2234210[abs_errors],3) -> 2.547165 | W25: cov(x,y)= | X25: =COVAR(Table2234210[REF],Table2234210[Ypred]) -> 1.2249448
C26: Least rectangle intercept= | E26: =D9-E25*F9 -> 5.4970267 | W26: sign(cov) | X26: =SIGN(X25) -> 1
C27: RMSEPrec= | E27: =SQRT(AVERAGE(Table2234210[dif_rec^2])) -> 1.2089624
W29: min resid= | X29: =MIN(Table2234210[X-Y]) -> -4.5345806 | Y29: =X29 -> -4.5345806
W30: max resid= | X30: =MAX(Table2234210[X-Y]) -> 2.9815676 | Y30: =X30 -> 2.9815676
X38: last point=
X39: =X8 -> 142 | Y39: the last point must be changed in serie 1 for X and Y
Y40: click in the graph
Y41: select data
X58: last point=
W59: =W60*E8 -> 8.6313868 | X59: =X39 -> 142
T60: =MEDIAN(Table2234210[abs(lab)]) -> 0.98999975 | V60: =MEDIAN(Table2234210[abs(anl)]) -> 1.4208774 | W60: =MEDIAN(Table2234210[Produits Lab x Anl]) -> 0.10789234
D61: Y | F61: X
B62: Position | C62: SN | D62: REF | E62: Column1 | F62: Ypred | G62: X-Y | H62: diff-bias | I62: Xbiased | J62: Yest | K62: RESyx | L62: Abs_erroryx | M62: yest_rect | N62: dif^2 | O62: dif rec | P62: dif_rec^2 | Q62: abs_errors | R62: Column3 | S62: lab-med | T62: abs(lab) | U62: anl-med | V62: abs(anl) | W62: Produits Lab x Anl | X62: =D62 -> REF | AA62: =F62 -> Ypred
B63: =VALUE((Table2234210[[#This Row],[Column3]]-62)) -> 1 | C63: S001 | D63: 9.9399996 | F63: 7.7669192 | G63: =Table2234210[[#This Row],[Ypred]]-Table2234210[[#This Row],[REF]] -> -2.1730804 | H63: =Table2234210[[#This Row],[X-Y]]-E$20 -> -2.0159599 | I63: =Table2234210[[#This Row],[Ypred]]-E$20 -> 7.9240397 | J63: =Table2234210[[#This Row],[Ypred]]*E$21+E$22 -> 10.355246 | K63: =Table2234210[[#This Row],[Yest]]-Table2234210[[#This Row],[REF]] -> 0.41524651 | L63: =ABS(Table2234210[[#This Row],[RESyx]]) -> 0.41524651 | M63: =Table2234210[[#This Row],[Ypred]]*E$25+E$26 -> 9.4771323 | N63: =Table2234210[[#This Row],[X-Y]]^2 -> 4.7222786 | O63: =Table2234210[[#This Row],[yest_rect]]-Table2234210[[#This Row],[REF]] -> -0.46286735 | P63: =Table2234210[[#This Row],[dif rec]]^2 -> 0.21424618 | Q63: =ABS(Table2234210[[#This Row],[diff-bias]]) -> 2.0159599 | R63: =CELL("row",Table2234210[[#This Row],[Position]]) -> 63 | S63: =Table2234210[[#This Row],[REF]]-D$13 -> -1.0700007 | T63: =ABS(Table2234210[[#This Row],[lab-med]]) -> 1.0700007 | U63: =Table2234210[[#This Row],[Ypred]]-F$13 -> -3.2287534 | V63: =ABS(Table2234210[[#This Row],[anl-med]]) -> 3.2287534 | W63: =Table2234210[[#This Row],[lab-med]]*Table2234210[[#This Row],[anl-med]] -> 3.4547682
B64: =VALUE((Table2234210[[#This Row],[Column3]]-62)) -> 2 | C64: S002 | D64: 10.020001 | F64: 12.395626 | G64: =Table2234210[[#This Row],[Ypred]]-Table2234210[[#This Row],[REF]] -> 2.3756252 | H64: =Table2234210[[#This Row],[X-Y]]-E$20 -> 2.5327457 | I64: =Table2234210[[#This Row],[Ypred]]-E$20 -> 12.552746 | J64: =Table2234210[[#This Row],[Ypred]]*E$21+E$22 -> 11.451232 | K64: =Table2234210[[#This Row],[Yest]]-Table2234210[[#This Row],[REF]] -> 1.4312316 | L64: =ABS(Table2234210[[#This Row],[RESyx]]) -> 1.4312316 | M64: =Table2234210[[#This Row],[Ypred]]*E$25+E$26 -> 11.849082 | N64: =Table2234210[[#This Row],[X-Y]]^2 -> 5.643595 | O64: =Table2234210[[#This Row],[yest_rect]]-Table2234210[[#This Row],[REF]] -> 1.8290813 | P64: =Table2234210[[#This Row],[dif rec]]^2 -> 3.3455385 | Q64: =ABS(Table2234210[[#This Row],[diff-bias]]) -> 2.5327457 | R64: =CELL("row",Table2234210[[#This Row],[Position]]) -> 64 | S64: =Table2234210[[#This Row],[REF]]-D$13 -> -0.98999975 | T64: =ABS(Table2234210[[#This Row],[lab-med]]) -> 0.98999975 | U64: =Table2234210[[#This Row],[Ypred]]-F$13 -> 1.3999531 | V64: =ABS(Table2234210[[#This Row],[anl-med]]) -> 1.3999531 | W64: =Table2234210[[#This Row],[lab-med]]*Table2234210[[#This Row],[anl-med]] -> -1.3859532
B65: =VALUE((Table2234210[[#This Row],[Column3]]-62)) -> 3 | C65: S003 | D65: 10 | F65: 5.9841559 | G65: =Table2234210[[#This Row],[Ypred]]-Table2234210[[#This Row],[REF]] -> -4.0158441 | H65: =Table2234210[[#This Row],[X-Y]]-E$20 -> -3.8587235 | I65: =Table2234210[[#This Row],[Ypred]]-E$20 -> 6.1412765 | J65: =Table2234210[[#This Row],[Ypred]]*E$21+E$22 -> 9.9331231 | K65: =Table2234210[[#This Row],[Yest]]-Table2234210[[#This Row],[REF]] -> -0.066876902 | L65: =ABS(Table2234210[[#This Row],[RESyx]]) -> 0.066876902 | M65: =Table2234210[[#This Row],[Ypred]]*E$25+E$26 -> 8.5635672 | N65: =Table2234210[[#This Row],[X-Y]]^2 -> 16.127004 | O65: =Table2234210[[#This Row],[yest_rect]]-Table2234210[[#This Row],[REF]] -> -1.4364328 | P65: =Table2234210[[#This Row],[dif rec]]^2 -> 2.0633392 | Q65: =ABS(Table2234210[[#This Row],[diff-bias]]) -> 3.8587235 | R65: =CELL("row",Table2234210[[#This Row],[Position]]) -> 65 | S65: =Table2234210[[#This Row],[REF]]-D$13 -> -1.0100003 | T65: =ABS(Table2234210[[#This Row],[lab-med]]) -> 1.0100003 | U65: =Table2234210[[#This Row],[Ypred]]-F$13 -> -5.0115166 | V65: =ABS(Table2234210[[#This Row],[anl-med]]) -> 5.0115166 | W65: =Table2234210[[#This Row],[lab-med]]*Table2234210[[#This Row],[anl-med]] -> 5.0616331
B66: =VALUE((Table2234210[[#This Row],[Column3]]-62)) -> 4 | C66: S004 | D66: 10.5 | F66: 12.900335 | G66: =Table2234210[[#This Row],[Ypred]]-Table2234210[[#This Row],[REF]] -> 2.4003349 | H66: =Table2234210[[#This Row],[X-Y]]-E$20 -> 2.5574555 | I66: =Table2234210[[#This Row],[Ypred]]-E$20 -> 13.057455 | J66: =Table2234210[[#This Row],[Ypred]]*E$21+E$22 -> 11.570737 | K66: =Table2234210[[#This Row],[Yest]]-Table2234210[[#This Row],[REF]] -> 1.0707372 | L66: =ABS(Table2234210[[#This Row],[RESyx]]) -> 1.0707372 | M66: =Table2234210[[#This Row],[Ypred]]*E$25+E$26 -> 12.107717 | N66: =Table2234210[[#This Row],[X-Y]]^2 -> 5.7616078 | O66: =Table2234210[[#This Row],[yest_rect]]-Table2234210[[#This Row],[REF]] -> 1.6077167 | P66: =Table2234210[[#This Row],[dif rec]]^2 -> 2.584753 | Q66: =ABS(Table2234210[[#This Row],[diff-bias]]) -> 2.5574555 | R66: =CELL("row",Table2234210[[#This Row],[Position]]) -> 66 | S66: =Table2234210[[#This Row],[REF]]-D$13 -> -0.51000025 | T66: =ABS(Table2234210[[#This Row],[lab-med]]) -> 0.51000025 | U66: =Table2234210[[#This Row],[Ypred]]-F$13 -> 1.9046624 | V66: =ABS(Table2234210[[#This Row],[anl-med]]) -> 1.9046624 | W66: =Table2234210[[#This Row],[lab-med]]*Table2234210[[#This Row],[anl-med]] -> -0.97137829
B67: =VALUE((Table2234210[[#This Row],[Column3]]-62)) -> 5 | C67: S005 | D67: 10.78 | F67: 6.2454191 | G67: =Table2234210[[#This Row],[Ypred]]-Table2234210[[#This Row],[REF]] -> -4.5345806 | H67: =Table2234210[[#This Row],[X-Y]]-E$20 -> -4.3774601 | I67: =Table2234210[[#This Row],[Ypred]]-E$20 -> 6.4025396 | J67: =Table2234210[[#This Row],[Ypred]]*E$21+E$22 -> 9.994985 | K67: =Table2234210[[#This Row],[Yest]]-Table2234210[[#This Row],[REF]] -> -0.78501466 | L67: =ABS(Table2234210[[#This Row],[RESyx]]) -> 0.78501466 | M67: =Table2234210[[#This Row],[Ypred]]*E$25+E$26 -> 8.6974498 | N67: =Table2234210[[#This Row],[X-Y]]^2 -> 20.562421 | O67: =Table2234210[[#This Row],[yest_rect]]-Table2234210[[#This Row],[REF]] -> -2.0825499 | P67: =Table2234210[[#This Row],[dif rec]]^2 -> 4.3370143 | Q67: =ABS(Table2234210[[#This Row],[diff-bias]]) -> 4.3774601 | R67: =CELL("row",Table2234210[[#This Row],[Position]]) -> 67 | S67: =Table2234210[[#This Row],[REF]]-D$13 -> -0.23000055 | T67: =ABS(Table2234210[[#This Row],[lab-med]]) -> 0.23000055 | U67: =Table2234210[[#This Row],[Ypred]]-F$13 -> -4.7502535 | V67: =ABS(Table2234210[[#This Row],[anl-med]]) -> 4.7502535 | W67: =Table2234210[[#This Row],[lab-med]]*Table2234210[[#This Row],[anl-med]] -> 1.0925609
...

Sheet OPEX
W1: INSTRUCTIONS
C3: OPEX STUDENTS
C6: =CONCATENATE(D62," = f (",F62," )") -> REF = f (Ypred ) | H6: CALIBRATION INFORMATION
D7: =D62 -> REF | F7: =F62 -> Ypred | H7: N= | I7: 500 | X7: last point=
C8: N= | E8: =COUNT(Table22342102[REF]) -> 80 | H8: SECV= | I8: 1.2 | X8: =62+E8 -> 142
C9: Average= | D9: =AVERAGE(Table22342102[REF]) -> 11.1095 | F9: =AVERAGE(Table22342102[Ypred]) -> 11.826979 | H9: Number of Terms = | J9: 12
C10: Min= | D10: =MIN(Table22342102[REF]) -> 8.9700003 | E10: =ROUNDDOWN(MIN(D10,F10),0) -> 8 | F10: =MIN(Table22342102[Ypred]) -> 9.043918 | H10: Alpha= | I10: 0.05 | W10: =E10+E20 -> 8.7174794
C11: Max= | D11: =MAX(Table22342102[REF]) -> 14.43 | E11: =ROUNDUP(MAX(D11,F11),0)+1 -> 17 | F11: =MAX(Table22342102[Ypred]) -> 15.525519 | H11: Tvalue= | I11: =TINV(I10,E8) -> 1.9900634 | W11: =E11+E20 -> 17.717479
C12: SD= | D12: =STDEV(Table22342102[REF]) -> 1.172905 | F12: =STDEV(Table22342102[Ypred]) -> 1.2349607 | H12: Fvalue= | I12: =FINV(I10,E8-1,I7-1-J9) -> 1.3057951
C13: Medians= | D13: =MEDIAN(Table22342102[REF]) -> 11.01 | F13: =MEDIAN(Table22342102[Ypred]) -> 11.723969
C14: SD_medians= | D14: =1.4826*(MEDIAN(Table22342102[abs(lab)])) -> 1.4677736 | F14: =1.4826*MEDIAN(Table22342102[abs(anl)]) -> 1.316832
F15: Robust(medians)
C16: RMSEP= | E16: =SQRT(AVERAGE(Table22342102[dif^2])) -> 1.0193594 | F16: =SQRT(F18^2+E20^2) -> 1.0757805
C17: Median ABS errors= | F17: =MEDIAN(Table22342102[abs_errors]) -> 0.54065684
C18: SEPC= | E18: =STDEV(Table22342102[X-Y]) -> 0.72866576 | F18: =1.4826*MEDIAN(Table22342102[abs_errors]) -> 0.80157784 | H18: F_sep= | I18: =I8*I12 -> 1.5669542 | J18: =IF(E18>I18,"S"," ns ") -> ns | X18: Yrec | Y18: Xrec
C19: RSDyx= | E19: =STEYX(Table22342102[REF],Table22342102[Ypred]) -> 0.6789016 | F19: =1.4826*MEDIAN(Table22342102[Abs_erroryx]) -> 0.66179356 | W19: y1rect= | X19: =E$26+E$25*E10 -> 7.474823 | Y19: =E10 -> 8
C20: BIAS= | E20: =F9-D9 -> 0.71747945 | F20: =F13-D13 -> 0.71396875 | H20: Tobs_bias= | I20: =ABS(E20/(SQRT(SUM(Table22342102[dif^2])/(E8*(E8-1))))) -> 6.2559846 | J20: =IF(I20>I11,"S","ns") -> S | W20: y2rect= | X20: =E$26+E$25*E11 -> 16.022581 | Y20: =E11 -> 17
C21: Slope= | E21: =SLOPE(Table22342102[REF],Table22342102[Ypred]) -> 0.77694474 | H21: Tobs_slope= | I21: =ABS(E21-1)*SQRT((E8-1)*F12^2/E19^2) -> 3.6063868 | J21: =IF(I21>I11,"S"," ns ") -> S | W21: ym= | X21: =E$26+E$25*F9 -> 11.1095 | Y21: =F9 -> 11.826979
C22: Intercept= | E22: =INTERCEPT(Table22342102[REF],Table22342102[Ypred]) -> 1.9205905
C23: RSQ= | E23: =RSQ(Table22342102[REF],Table22342102[Ypred]) -> 0.66920761 | F23: =(D12^2-F19^2)/D12^2 -> 0.68163933
C24: RPD= | E24: =1/SQRT(1-E23) -> 1.7386903 | F24: =1/SQRT(1-F23) -> 1.7723125 | H24: RPD2= | I24: =D12/E19 -> 1.7276509
C25: Least rectangle slope= | E25: =(D12/F12) -> 0.94975087 | H25: Quartile75= | I25: =QUARTILE(Table22342102[abs_errors],3) -> 0.88844833 | W25: cov(x,y)= | X25: =COVAR(Table22342102[REF],Table22342102[Ypred]) -> 1.1701284
C26: Least rectangle intercept= | E26: =D9-E25*F9 -> -0.12318396 | W26: sign(cov) | X26: =SIGN(X25) -> 1
C27: RMSEPrec= | E27: =SQRT(AVERAGE(Table22342102[dif_rec^2])) -> 0.70310647
W29: min resid= | X29: =MIN(Table22342102[X-Y]) -> -1.0720791 | Y29: =X29 -> -1.0720791
W30: max resid= | X30: =MAX(Table22342102[X-Y]) -> 2.0450409 | Y30: =X30 -> 2.0450409
X38: last point=
X39: =X8 -> 142 | Y39: the last point must be changed in serie 1 for X and Y
Y40: click in the graph
Y41: select data
X58: last point=
W59: =W60*E8 -> 48.662407 | X59: =X39 -> 142
T60: =MEDIAN(Table22342102[abs(lab)]) -> 0.98999975 | V60: =MEDIAN(Table22342102[abs(anl)]) -> 0.888191 | W60: =MEDIAN(Table22342102[Produits Lab x Anl]) -> 0.60828009
D61: Y | F61: X
B62: Position | C62: SN | D62: REF | E62: Column1 | F62: Ypred | G62: X-Y | H62: diff-bias | I62: Xbiased | J62: Yest | K62: RESyx | L62: Abs_erroryx | M62: yest_rect | N62: dif^2 | O62: dif rec | P62: dif_rec^2 | Q62: abs_errors | R62: Column3 | S62: lab-med | T62: abs(lab) | U62: anl-med | V62: abs(anl) | W62: Produits Lab x Anl | X62: =D62 -> REF | AA62: =F62 -> Ypred
B63: =VALUE((Table22342102[[#This Row],[Column3]]-62)) -> 1 | C63: S001 | D63: 9.9399996 | F63: 10.118334 | G63: =Table22342102[[#This Row],[Ypred]]-Table22342102[[#This Row],[REF]] -> 0.1783344 | H63: =Table22342102[[#This Row],[X-Y]]-E$20 -> -0.53914504 | I63: =Table22342102[[#This Row],[Ypred]]-E$20 -> 9.4008546 | J63: =Table22342102[[#This Row],[Ypred]]*E$21+E$22 -> 9.7819769 | K63: =Table22342102[[#This Row],[Yest]]-Table22342102[[#This Row],[REF]] -> -0.1580227 | L63: =ABS(Table22342102[[#This Row],[RESyx]]) -> 0.1580227 | M63: =Table22342102[[#This Row],[Ypred]]*E$25+E$26 -> 9.4867125 | N63: =Table22342102[[#This Row],[X-Y]]^2 -> 0.031803158 | O63: =Table22342102[[#This Row],[yest_rect]]-Table22342102[[#This Row],[REF]] -> -0.45328709 | P63: =Table22342102[[#This Row],[dif rec]]^2 -> 0.20546919 | Q63: =ABS(Table22342102[[#This Row],[diff-bias]]) -> 0.53914504 | R63: =CELL("row",Table22342102[[#This Row],[Position]]) -> 63 | S63: =Table22342102[[#This Row],[REF]]-D$13 -> -1.0700007 | T63: =ABS(Table22342102[[#This Row],[lab-med]]) -> 1.0700007 | U63: =Table22342102[[#This Row],[Ypred]]-F$13 -> -1.605635 | V63: =ABS(Table22342102[[#This Row],[anl-med]]) -> 1.605635 | W63: =Table22342102[[#This Row],[lab-med]]*Table22342102[[#This Row],[anl-med]] -> 1.7180305
B64: =VALUE((Table22342102[[#This Row],[Column3]]-62)) -> 2 | C64: S002 | D64: 10.020001 | F64: 10.84305 | G64: =Table22342102[[#This Row],[Ypred]]-Table22342102[[#This Row],[REF]] -> 0.8230495 | H64: =Table22342102[[#This Row],[X-Y]]-E$20 -> 0.10557005 | I64: =Table22342102[[#This Row],[Ypred]]-E$20 -> 10.125571 | J64: =Table22342102[[#This Row],[Ypred]]*E$21+E$22 -> 10.345041 | K64: =Table22342102[[#This Row],[Yest]]-Table22342102[[#This Row],[REF]] -> 0.32504069 | L64: =ABS(Table22342102[[#This Row],[RESyx]]) -> 0.32504069 | M64: =Table22342102[[#This Row],[Ypred]]*E$25+E$26 -> 10.175012 | N64: =Table22342102[[#This Row],[X-Y]]^2 -> 0.67741048 | O64: =Table22342102[[#This Row],[yest_rect]]-Table22342102[[#This Row],[REF]] -> 0.15501166 | P64: =Table22342102[[#This Row],[dif rec]]^2 -> 0.024028614 | Q64: =ABS(Table22342102[[#This Row],[diff-bias]]) -> 0.10557005 | R64: =CELL("row",Table22342102[[#This Row],[Position]]) -> 64 | S64: =Table22342102[[#This Row],[REF]]-D$13 -> -0.98999975 | T64: =ABS(Table22342102[[#This Row],[lab-med]]) -> 0.98999975 | U64: =Table22342102[[#This Row],[Ypred]]-F$13 -> -0.880919 | V64: =ABS(Table22342102[[#This Row],[anl-med]]) -> 0.880919 | W64: =Table22342102[[#This Row],[lab-med]]*Table22342102[[#This Row],[anl-med]] -> 0.87210959
B65: =VALUE((Table22342102[[#This Row],[Column3]]-62)) -> 3 | C65: S003 | D65: 10 | F65: 10.022606 | G65: =Table22342102[[#This Row],[Ypred]]-Table22342102[[#This Row],[REF]] -> 0.022606 | H65: =Table22342102[[#This Row],[X-Y]]-E$20 -> -0.69487345 | I65: =Table22342102[[#This Row],[Ypred]]-E$20 -> 9.3051266 | J65: =Table22342102[[#This Row],[Ypred]]*E$21+E$22 -> 9.7076015 | K65: =Table22342102[[#This Row],[Yest]]-Table22342102[[#This Row],[REF]] -> -0.29239847 | L65: =ABS(Table22342102[[#This Row],[RESyx]]) -> 0.29239847 | M65: =Table22342102[[#This Row],[Ypred]]*E$25+E$26 -> 9.3957948 | N65: =Table22342102[[#This Row],[X-Y]]^2 -> 0.00051103124 | O65: =Table22342102[[#This Row],[yest_rect]]-Table22342102[[#This Row],[REF]] -> -0.60420524 | P65: =Table22342102[[#This Row],[dif rec]]^2 -> 0.36506397 | Q65: =ABS(Table22342102[[#This Row],[diff-bias]]) -> 0.69487345 | R65: =CELL("row",Table22342102[[#This Row],[Position]]) -> 65 | S65: =Table22342102[[#This Row],[REF]]-D$13 -> -1.0100003 | T65: =ABS(Table22342102[[#This Row],[lab-med]]) -> 1.0100003 | U65: =Table22342102[[#This Row],[Ypred]]-F$13 -> -1.701363 | V65: =ABS(Table22342102[[#This Row],[anl-med]]) -> 1.701363 | W65: =Table22342102[[#This Row],[lab-med]]*Table22342102[[#This Row],[anl-med]] -> 1.7183771
B66: =VALUE((Table22342102[[#This Row],[Column3]]-62)) -> 4 | C66: S004 | D66: 10.5 | F66: 11.288049 | G66: =Table22342102[[#This Row],[Ypred]]-Table22342102[[#This Row],[REF]] -> 0.788049 | H66: =Table22342102[[#This Row],[X-Y]]-E$20 -> 0.070569555 | I66: =Table22342102[[#This Row],[Ypred]]-E$20 -> 10.57057 | J66: =Table22342102[[#This Row],[Ypred]]*E$21+E$22 -> 10.690781 | K66: =Table22342102[[#This Row],[Yest]]-Table22342102[[#This Row],[REF]] -> 0.19078082 | L66: =ABS(Table22342102[[#This Row],[RESyx]]) -> 0.19078082 | M66: =Table22342102[[#This Row],[Ypred]]*E$25+E$26 -> 10.59765 | N66: =Table22342102[[#This Row],[X-Y]]^2 -> 0.62102123 | O66: =Table22342102[[#This Row],[yest_rect]]-Table22342102[[#This Row],[REF]] -> 0.097650343 | P66: =Table22342102[[#This Row],[dif rec]]^2 -> 0.0095355894 | Q66: =ABS(Table22342102[[#This Row],[diff-bias]]) -> 0.070569555 | R66: =CELL("row",Table22342102[[#This Row],[Position]]) -> 66 | S66: =Table22342102[[#This Row],[REF]]-D$13 -> -0.51000025 | T66: =ABS(Table22342102[[#This Row],[lab-med]]) -> 0.51000025 | U66: =Table22342102[[#This Row],[Ypred]]-F$13 -> -0.43592 | V66: =ABS(Table22342102[[#This Row],[anl-med]]) -> 0.43592 | W66: =Table22342102[[#This Row],[lab-med]]*Table22342102[[#This Row],[anl-med]] -> 0.22231931
B67: =VALUE((Table22342102[[#This Row],[Column3]]-62)) -> 5 | C67: S005 | D67: 10.78 | F67: 10.828506 | G67: =Table22342102[[#This Row],[Ypred]]-Table22342102[[#This Row],[REF]] -> 0.0485063 | H67: =Table22342102[[#This Row],[X-Y]]-E$20 -> -0.66897314 | I67: =Table22342102[[#This Row],[Ypred]]-E$20 -> 10.111027 | J67: =Table22342102[[#This Row],[Ypred]]*E$21+E$22 -> 10.333741 | K67: =Table22342102[[#This Row],[Yest]]-Table22342102[[#This Row],[REF]] -> -0.4462584 | L67: =ABS(Table22342102[[#This Row],[RESyx]]) -> 0.4462584 | M67: =Table22342102[[#This Row],[Ypred]]*E$25+E$26 -> 10.161199 | N67: =Table22342102[[#This Row],[X-Y]]^2 -> 0.0023528611 | O67: =Table22342102[[#This Row],[yest_rect]]-Table22342102[[#This Row],[REF]] -> -0.61880072 | P67: =Table22342102[[#This Row],[dif rec]]^2 -> 0.38291433 | Q67: =ABS(Table22342102[[#This Row],[diff-bias]]) -> 0.66897314 | R67: =CELL("row",Table22342102[[#This Row],[Position]]) -> 67 | S67: =Table22342102[[#This Row],[REF]]-D$13 -> -0.23000055 | T67: =ABS(Table22342102[[#This Row],[lab-med]]) -> 0.23000055 | U67: =Table22342102[[#This Row],[Ypred]]-F$13 -> -0.895463 | V67: =ABS(Table22342102[[#This Row],[anl-med]]) -> 0.895463 | W67: =Table22342102[[#This Row],[lab-med]]*Table22342102[[#This Row],[anl-med]] -> 0.20595698
...

Sheet Lijour
W1: INSTRUCTIONS
C3: Lijour
C6: =CONCATENATE(D62," = f (",F62," )") -> REF = f (yval ) | H6: CALIBRATION INFORMATION
D7: =D62 -> REF | F7: =F62 -> yval | H7: N= | I7: 500 | X7: last point=
C8: N= | E8: =COUNT(Table223421023[REF]) -> 80 | H8: SECV= | I8: 1.2 | X8: =62+E8 -> 142
C9: Average= | D9: =AVERAGE(Table223421023[REF]) -> 11.1095 | F9: =AVERAGE(Table223421023[yval]) -> 11.887997 | H9: Number of Terms = | J9: 12
C10: Min= | D10: =MIN(Table223421023[REF]) -> 8.9700003 | E10: =ROUNDDOWN(MIN(D10,F10),0) -> 5 | F10: =MIN(Table223421023[yval]) -> 5.7431371 | H10: Alpha= | I10: 0.05 | W10: =E10+E20 -> 5.778497
C11: Max= | D11: =MAX(Table223421023[REF]) -> 14.43 | E11: =ROUNDUP(MAX(D11,F11),0)+1 -> 18 | F11: =MAX(Table223421023[yval]) -> 16.424855 | H11: Tvalue= | I11: =TINV(I10,E8) -> 1.9900634 | W11: =E11+E20 -> 18.778497
C12: SD= | D12: =STDEV(Table223421023[REF]) -> 1.172905 | F12: =STDEV(Table223421023[yval]) -> 2.0323718 | H12: Fvalue= | I12: =FINV(I10,E8-1,I7-1-J9) -> 1.3057951
C13: Medians= | D13: =MEDIAN(Table223421023[REF]) -> 11.01 | F13: =MEDIAN(Table223421023[yval]) -> 11.967787
C14: SD_medians= | D14: =1.4826*(MEDIAN(Table223421023[abs(lab)])) -> 1.4677736 | F14: =1.4826*MEDIAN(Table223421023[abs(anl)]) -> 1.8605665
F15: Robust(medians)
C16: RMSEP= | E16: =SQRT(AVERAGE(Table223421023[dif^2])) -> 2.2456576 | F16: =SQRT(F18^2+E20^2) -> 2.2116705
C17: Median ABS errors= | F17: =MEDIAN(Table223421023[abs_errors]) -> 1.396282
C18: SEPC= | E18: =STDEV(Table223421023[X-Y]) -> 2.1196896 | F18: =1.4826*MEDIAN(Table223421023[abs_errors]) -> 2.0701277 | H18: F_sep= | I18: =I8*I12 -> 1.5669542 | J18: =IF(E18>I18,"S"," ns ") -> S | X18: Yrec | Y18: Xrec
C19: RSDyx= | E19: =STEYX(Table223421023[REF],Table223421023[yval]) -> 1.1534378 | F19: =1.4826*MEDIAN(Table223421023[Abs_erroryx]) -> 1.2699536 | W19: y1rect= | X19: =E$26+E$25*E10 -> 7.1343582 | Y19: =E10 -> 5
C20: BIAS= | E20: =F9-D9 -> 0.77849698 | F20: =F13-D13 -> 0.95778715 | H20: Tobs_bias= | I20: =ABS(E20/(SQRT(SUM(Table223421023[dif^2])/(E8*(E8-1))))) -> 3.0812501 | J20: =IF(I20>I11,"S","ns") -> S | W20: y2rect= | X20: =E$26+E$25*E11 -> 14.636807 | Y20: =E11 -> 18
C21: Slope= | E21: =SLOPE(Table223421023[REF],Table223421023[yval]) -> 0.12264239 | H21: Tobs_slope= | I21: =ABS(E21-1)*SQRT((E8-1)*F12^2/E19^2) -> 13.740393 | J21: =IF(I21>I11,"S"," ns ") -> S | W21: ym= | X21: =E$26+E$25*F9 -> 11.1095 | Y21: =F9 -> 11.887997
C22: Intercept= | E22: =INTERCEPT(Table223421023[REF],Table223421023[yval]) -> 9.6515277
C23: RSQ= | E23: =RSQ(Table223421023[REF],Table223421023[yval]) -> 0.045160822 | F23: =(D12^2-F19^2)/D12^2 -> -0.17233048
C24: RPD= | E24: =1/SQRT(1-E23) -> 1.0233752 | F24: =1/SQRT(1-F23) -> 0.92358096 | H24: RPD2= | I24: =D12/E19 -> 1.0168775
C25: Least rectangle slope= | E25: =(D12/F12) -> 0.57711142 | H25: Quartile75= | I25: =QUARTILE(Table223421023[abs_errors],3) -> 2.3849212 | W25: cov(x,y)= | X25: =COVAR(Table223421023[REF],Table223421023[yval]) -> 0.50024645
C26: Least rectangle intercept= | E26: =D9-E25*F9 -> 4.2488011 | W26: sign(cov) | X26: =SIGN(X25) -> 1
C27: RMSEPrec= | E27: =SQRT(AVERAGE(Table223421023[dif_rec^2])) -> 1.4627452
W29: min resid= | X29: =MIN(Table223421023[X-Y]) -> -6.9568627 | Y29: =X29 -> -6.9568627
W30: max resid= | X30: =MAX(Table223421023[X-Y]) -> 6.3248549 | Y30: =X30 -> 6.3248549
X38: last point=
X39: =X8 -> 142 | Y39: the last point must be changed in serie 1 for X and Y
Y40: click in the graph
Y41: select data
X58: last point=
W59: =W60*E8 -> 2.7529602 | X59: =X39 -> 142
T60: =MEDIAN(Table223421023[abs(lab)]) -> 0.98999975 | V60: =MEDIAN(Table223421023[abs(anl)]) -> 1.2549349 | W60: =MEDIAN(Table223421023[Produits Lab x Anl]) -> 0.034412002
D61: Y | F61: X
B62: Position | C62: SN | D62: REF | E62: Column1 | F62: yval | G62: X-Y | H62: diff-bias | I62: Xbiased | J62: Yest | K62: RESyx | L62: Abs_erroryx | M62: yest_rect | N62: dif^2 | O62: dif rec | P62: dif_rec^2 | Q62: abs_errors | R62: Column3 | S62: lab-med | T62: abs(lab) | U62: anl-med | V62: abs(anl) | W62: Produits Lab x Anl | X62: =D62 -> REF | AA62: =F62 -> yval
B63: =VALUE((Table223421023[[#This Row],[Column3]]-62)) -> 1 | C63: S001 | D63: 9.9399996 | F63: 9.1510476 | G63: =Table223421023[[#This Row],[yval]]-Table223421023[[#This Row],[REF]] -> -0.78895195 | H63: =Table223421023[[#This Row],[X-Y]]-E$20 -> -1.5674489 | I63: =Table223421023[[#This Row],[yval]]-E$20 -> 8.3725507 | J63: =Table223421023[[#This Row],[yval]]*E$21+E$22 -> 10.773834 | K63: =Table223421023[[#This Row],[Yest]]-Table223421023[[#This Row],[REF]] -> 0.83383439 | L63: =ABS(Table223421023[[#This Row],[RESyx]]) -> 0.83383439 | M63: =Table223421023[[#This Row],[yval]]*E$25+E$26 -> 9.5299753 | N63: =Table223421023[[#This Row],[X-Y]]^2 -> 0.62244519 | O63: =Table223421023[[#This Row],[yest_rect]]-Table223421023[[#This Row],[REF]] -> -0.41002434 | P63: =Table223421023[[#This Row],[dif rec]]^2 -> 0.16811996 | Q63: =ABS(Table223421023[[#This Row],[diff-bias]]) -> 1.5674489 | R63: =CELL("row",Table223421023[[#This Row],[Position]]) -> 63 | S63: =Table223421023[[#This Row],[REF]]-D$13 -> -1.0700007 | T63: =ABS(Table223421023[[#This Row],[lab-med]]) -> 1.0700007 | U63: =Table223421023[[#This Row],[yval]]-F$13 -> -2.8167398 | V63: =ABS(Table223421023[[#This Row],[anl-med]]) -> 2.8167398 | W63: =Table223421023[[#This Row],[lab-med]]*Table223421023[[#This Row],[anl-med]] -> 3.0139134
B64: =VALUE((Table223421023[[#This Row],[Column3]]-62)) -> 2 | C64: S002 | D64: 10.020001 | F64: 13.223969 | G64: =Table223421023[[#This Row],[yval]]-Table223421023[[#This Row],[REF]] -> 3.2039683 | H64: =Table223421023[[#This Row],[X-Y]]-E$20 -> 2.4254713 | I64: =Table223421023[[#This Row],[yval]]-E$20 -> 12.445472 | J64: =Table223421023[[#This Row],[yval]]*E$21+E$22 -> 11.273347 | K64: =Table223421023[[#This Row],[Yest]]-Table223421023[[#This Row],[REF]] -> 1.2533462 | L64: =ABS(Table223421023[[#This Row],[RESyx]]) -> 1.2533462 | M64: =Table223421023[[#This Row],[yval]]*E$25+E$26 -> 11.880505 | N64: =Table223421023[[#This Row],[X-Y]]^2 -> 10.265413 | O64: =Table223421023[[#This Row],[yest_rect]]-Table223421023[[#This Row],[REF]] -> 1.8605041 | P64: =Table223421023[[#This Row],[dif rec]]^2 -> 3.4614754 | Q64: =ABS(Table223421023[[#This Row],[diff-bias]]) -> 2.4254713 | R64: =CELL("row",Table223421023[[#This Row],[Position]]) -> 64 | S64: =Table223421023[[#This Row],[REF]]-D$13 -> -0.98999975 | T64: =ABS(Table223421023[[#This Row],[lab-med]]) -> 0.98999975 | U64: =Table223421023[[#This Row],[yval]]-F$13 -> 1.2561814 | V64: =ABS(Table223421023[[#This Row],[anl-med]]) -> 1.2561814 | W64: =Table223421023[[#This Row],[lab-med]]*Table223421023[[#This Row],[anl-med]] -> -1.2436192
B65: =VALUE((Table223421023[[#This Row],[Column3]]-62)) -> 3 | C65: S003 | D65: 10 | F65: 7.8469075 | G65: =Table223421023[[#This Row],[yval]]-Table223421023[[#This Row],[REF]] -> -2.1530925 | H65: =Table223421023[[#This Row],[X-Y]]-E$20 -> -2.9315894 | I65: =Table223421023[[#This Row],[yval]]-E$20 -> 7.0684106 | J65: =Table223421023[[#This Row],[yval]]*E$21+E$22 -> 10.613891 | K65: =Table223421023[[#This Row],[Yest]]-Table223421023[[#This Row],[REF]] -> 0.61389113 | L65: =ABS(Table223421023[[#This Row],[RESyx]]) -> 0.61389113 | M65: =Table223421023[[#This Row],[yval]]*E$25+E$26 -> 8.7773411 | N65: =Table223421023[[#This Row],[X-Y]]^2 -> 4.6358071 | O65: =Table223421023[[#This Row],[yest_rect]]-Table223421023[[#This Row],[REF]] -> -1.2226589 | P65: =Table223421023[[#This Row],[dif rec]]^2 -> 1.4948948 | Q65: =ABS(Table223421023[[#This Row],[diff-bias]]) -> 2.9315894 | R65: =CELL("row",Table223421023[[#This Row],[Position]]) -> 65 | S65: =Table223421023[[#This Row],[REF]]-D$13 -> -1.0100003 | T65: =ABS(Table223421023[[#This Row],[lab-med]]) -> 1.0100003 | U65: =Table223421023[[#This Row],[yval]]-F$13 -> -4.1208798 | V65: =ABS(Table223421023[[#This Row],[anl-med]]) -> 4.1208798 | W65: =Table223421023[[#This Row],[lab-med]]*Table223421023[[#This Row],[anl-med]] -> 4.1620897
B66: =VALUE((Table223421023[[#This Row],[Column3]]-62)) -> 4 | C66: S004 | D66: 10.5 | F66: 14.062268 | G66: =Table223421023[[#This Row],[yval]]-Table223421023[[#This Row],[REF]] -> 3.5622684 | H66: =Table223421023[[#This Row],[X-Y]]-E$20 -> 2.7837714 | I66: =Table223421023[[#This Row],[yval]]-E$20 -> 13.283771 | J66: =Table223421023[[#This Row],[yval]]*E$21+E$22 -> 11.376158 | K66: =Table223421023[[#This Row],[Yest]]-Table223421023[[#This Row],[REF]] -> 0.87615782 | L66: =ABS(Table223421023[[#This Row],[RESyx]]) -> 0.87615782 | M66: =Table223421023[[#This Row],[yval]]*E$25+E$26 -> 12.364297 | N66: =Table223421023[[#This Row],[X-Y]]^2 -> 12.689756 | O66: =Table223421023[[#This Row],[yest_rect]]-Table223421023[[#This Row],[REF]] -> 1.8642969 | P66: =Table223421023[[#This Row],[dif rec]]^2 -> 3.4756028 | Q66: =ABS(Table223421023[[#This Row],[diff-bias]]) -> 2.7837714 | R66: =CELL("row",Table223421023[[#This Row],[Position]]) -> 66 | S66: =Table223421023[[#This Row],[REF]]-D$13 -> -0.51000025 | T66: =ABS(Table223421023[[#This Row],[lab-med]]) -> 0.51000025 | U66: =Table223421023[[#This Row],[yval]]-F$13 -> 2.094481 | V66: =ABS(Table223421023[[#This Row],[anl-med]]) -> 2.094481 | W66: =Table223421023[[#This Row],[lab-med]]*Table223421023[[#This Row],[anl-med]] -> -1.0681858
B67: =VALUE((Table223421023[[#This Row],[Column3]]-62)) -> 5 | C67: S005 | D67: 10.78 | F67: 7.9940292 | G67: =Table223421023[[#This Row],[yval]]-Table223421023[[#This Row],[REF]] -> -2.7859705 | H67: =Table223421023[[#This Row],[X-Y]]-E$20 -> -3.5644675 | I67: =Table223421023[[#This Row],[yval]]-E$20 -> 7.2155322 | J67: =Table223421023[[#This Row],[yval]]*E$21+E$22 -> 10.631934 | K67: =Table223421023[[#This Row],[Yest]]-Table223421023[[#This Row],[REF]] -> -0.14806522 | L67: =ABS(Table223421023[[#This Row],[RESyx]]) -> 0.14806522 | M67: =Table223421023[[#This Row],[yval]]*E$25+E$26 -> 8.8622467 | N67: =Table223421023[[#This Row],[X-Y]]^2 -> 7.7616318 | O67: =Table223421023[[#This Row],[yest_rect]]-Table223421023[[#This Row],[REF]] -> -1.917753 | P67: =Table223421023[[#This Row],[dif rec]]^2 -> 3.6777766 | Q67: =ABS(Table223421023[[#This Row],[diff-bias]]) -> 3.5644675 | R67: =CELL("row",Table223421023[[#This Row],[Position]]) -> 67 | S67: =Table223421023[[#This Row],[REF]]-D$13 -> -0.23000055 | T67: =ABS(Table223421023[[#This Row],[lab-med]]) -> 0.23000055 | U67: =Table223421023[[#This Row],[yval]]-F$13 -> -3.9737582 | V67: =ABS(Table223421023[[#This Row],[anl-med]]) -> 3.9737582 | W67: =Table223421023[[#This Row],[lab-med]]*Table223421023[[#This Row],[anl-med]] -> 0.91396658
...

Sheet Loudiyi 
W1: INSTRUCTIONS
C3: Loudiyi Mohammed
C6: =CONCATENATE(D62," = f (",F62," )") -> REF = f (Y_pred ) | H6: CALIBRATION INFORMATION
D7: =D62 -> REF | F7: =F62 -> Y_pred | H7: N= | I7: 500 | X7: last point=
C8: N= | E8: =COUNT(Table2234210234[REF]) -> 80 | H8: SECV= | I8: 1.2 | X8: =62+E8 -> 142
C9: Average= | D9: =AVERAGE(Table2234210234[REF]) -> 11.1095 | F9: =AVERAGE(Table2234210234[Y_pred]) -> 11.879705 | H9: Number of Terms = | J9: 12
C10: Min= | D10: =MIN(Table2234210234[REF]) -> 8.9700003 | E10: =ROUNDDOWN(MIN(D10,F10),0) -> 8 | F10: =MIN(Table2234210234[Y_pred]) -> 8.0820684 | H10: Alpha= | I10: 0.05 | W10: =E10+E20 -> 8.7702053
C11: Max= | D11: =MAX(Table2234210234[REF]) -> 14.43 | E11: =ROUNDUP(MAX(D11,F11),0)+1 -> 17 | F11: =MAX(Table2234210234[Y_pred]) -> 15.994986 | H11: Tvalue= | I11: =TINV(I10,E8) -> 1.9900634 | W11: =E11+E20 -> 17.770205
C12: SD= | D12: =STDEV(Table2234210234[REF]) -> 1.172905 | F12: =STDEV(Table2234210234[Y_pred]) -> 1.6051378 | H12: Fvalue= | I12: =FINV(I10,E8-1,I7-1-J9) -> 1.3057951
C13: Medians= | D13: =MEDIAN(Table2234210234[REF]) -> 11.01 | F13: =MEDIAN(Table2234210234[Y_pred]) -> 11.777338
C14: SD_medians= | D14: =1.4826*(MEDIAN(Table2234210234[abs(lab)])) -> 1.4677736 | F14: =1.4826*MEDIAN(Table2234210234[abs(anl)]) -> 1.726164
F15: Robust(medians)
C16: RMSEP= | E16: =SQRT(AVERAGE(Table2234210234[dif^2])) -> 1.4587482 | F16: =SQRT(F18^2+E20^2) -> 1.6755537
C17: Median ABS errors= | F17: =MEDIAN(Table2234210234[abs_errors]) -> 1.0036694
C18: SEPC= | E18: =STDEV(Table2234210234[X-Y]) -> 1.2466584 | F18: =1.4826*MEDIAN(Table2234210234[abs_errors]) -> 1.4880403 | H18: F_sep= | I18: =I8*I12 -> 1.5669542 | J18: =IF(E18>I18,"S"," ns ") -> ns | X18: Yrec | Y18: Xrec
C19: RSDyx= | E19: =STEYX(Table2234210234[REF],Table2234210234[Y_pred]) -> 0.9100596 | F19: =1.4826*MEDIAN(Table2234210234[Abs_erroryx]) -> 0.91228183 | W19: y1rect= | X19: =E$26+E$25*E10 -> 8.274525 | Y19: =E10 -> 8
C20: BIAS= | E20: =F9-D9 -> 0.77020527 | F20: =F13-D13 -> 0.76733744 | H20: Tobs_bias= | I20: =ABS(E20/(SQRT(SUM(Table2234210234[dif^2])/(E8*(E8-1))))) -> 4.6928826 | J20: =IF(I20>I11,"S","ns") -> S | W20: y2rect= | X20: =E$26+E$25*E11 -> 14.850997 | Y20: =E11 -> 17
C21: Slope= | E21: =SLOPE(Table2234210234[REF],Table2234210234[Y_pred]) -> 0.46536903 | H21: Tobs_slope= | I21: =ABS(E21-1)*SQRT((E8-1)*F12^2/E19^2) -> 8.3812763 | J21: =IF(I21>I11,"S"," ns ") -> S | W21: ym= | X21: =E$26+E$25*F9 -> 11.1095 | Y21: =F9 -> 11.879705
C22: Intercept= | E22: =INTERCEPT(Table2234210234[REF],Table2234210234[Y_pred]) -> 5.5810531
C23: RSQ= | E23: =RSQ(Table2234210234[REF],Table2234210234[Y_pred]) -> 0.40559628 | F23: =(D12^2-F19^2)/D12^2 -> 0.39503202
C24: RPD= | E24: =1/SQRT(1-E23) -> 1.2970575 | F24: =1/SQRT(1-F23) -> 1.2856827 | H24: RPD2= | I24: =D12/E19 -> 1.2888222
C25: Least rectangle slope= | E25: =(D12/F12) -> 0.73071916 | H25: Quartile75= | I25: =QUARTILE(Table2234210234[abs_errors],3) -> 1.4629787 | W25: cov(x,y)= | X25: =COVAR(Table2234210234[REF],Table2234210234[Y_pred]) -> 1.1840206
C26: Least rectangle intercept= | E26: =D9-E25*F9 -> 2.4287717 | W26: sign(cov) | X26: =SIGN(X25) -> 1
C27: RMSEPrec= | E27: =SQRT(AVERAGE(Table2234210234[dif_rec^2])) -> 0.9933008
W29: min resid= | X29: =MIN(Table2234210234[X-Y]) -> -2.2302699 | Y29: =X29 -> -2.2302699
W30: max resid= | X30: =MAX(Table2234210234[X-Y]) -> 3.5037329 | Y30: =X30 -> 3.5037329
X38: last point=
X39: =X8 -> 142 | Y39: the last point must be changed in serie 1 for X and Y
Y40: click in the graph
Y41: select data
X58: last point=
W59: =W60*E8 -> 53.27751 | X59: =X39 -> 142
T60: =MEDIAN(Table2234210234[abs(lab)]) -> 0.98999975 | V60: =MEDIAN(Table2234210234[abs(anl)]) -> 1.1642817 | W60: =MEDIAN(Table2234210234[Produits Lab x Anl]) -> 0.66596887
D61: Y | F61: X
B62: Position | C62: SN | D62: REF | E62: Column1 | F62: Y_pred | G62: X-Y | H62: diff-bias | I62: Xbiased | J62: Yest | K62: RESyx | L62: Abs_erroryx | M62: yest_rect | N62: dif^2 | O62: dif rec | P62: dif_rec^2 | Q62: abs_errors | R62: Column3 | S62: lab-med | T62: abs(lab) | U62: anl-med | V62: abs(anl) | W62: Produits Lab x Anl | X62: =D62 -> REF | AA62: =F62 -> Y_pred
B63: =VALUE((Table2234210234[[#This Row],[Column3]]-62)) -> 1 | C63: S001 | D63: 9.9399996 | F63: 9.590783 | G63: =Table2234210234[[#This Row],[Y_pred]]-Table2234210234[[#This Row],[REF]] -> -0.34921664 | H63: =Table2234210234[[#This Row],[X-Y]]-E$20 -> -1.1194219 | I63: =Table2234210234[[#This Row],[Y_pred]]-E$20 -> 8.8205777 | J63: =Table2234210234[[#This Row],[Y_pred]]*E$21+E$22 -> 10.044306 | K63: =Table2234210234[[#This Row],[Yest]]-Table2234210234[[#This Row],[REF]] -> 0.10430683 | L63: =ABS(Table2234210234[[#This Row],[RESyx]]) -> 0.10430683 | M63: =Table2234210234[[#This Row],[Y_pred]]*E$25+E$26 -> 9.4369406 | N63: =Table2234210234[[#This Row],[X-Y]]^2 -> 0.12195226 | O63: =Table2234210234[[#This Row],[yest_rect]]-Table2234210234[[#This Row],[REF]] -> -0.503059 | P63: =Table2234210234[[#This Row],[dif rec]]^2 -> 0.25306836 | Q63: =ABS(Table2234210234[[#This Row],[diff-bias]]) -> 1.1194219 | R63: =CELL("row",Table2234210234[[#This Row],[Position]]) -> 63 | S63: =Table2234210234[[#This Row],[REF]]-D$13 -> -1.0700007 | T63: =ABS(Table2234210234[[#This Row],[lab-med]]) -> 1.0700007 | U63: =Table2234210234[[#This Row],[Y_pred]]-F$13 -> -2.1865547 | V63: =ABS(Table2234210234[[#This Row],[anl-med]]) -> 2.1865547 | W63: =Table2234210234[[#This Row],[lab-med]]*Table2234210234[[#This Row],[anl-med]] -> 2.339615
B64: =VALUE((Table2234210234[[#This Row],[Column3]]-62)) -> 2 | C64: S002 | D64: 10.020001 | F64: 12.812301 | G64: =Table2234210234[[#This Row],[Y_pred]]-Table2234210234[[#This Row],[REF]] -> 2.7923003 | H64: =Table2234210234[[#This Row],[X-Y]]-E$20 -> 2.022095 | I64: =Table2234210234[[#This Row],[Y_pred]]-E$20 -> 12.042096 | J64: =Table2234210234[[#This Row],[Y_pred]]*E$21+E$22 -> 11.543501 | K64: =Table2234210234[[#This Row],[Yest]]-Table2234210234[[#This Row],[REF]] -> 1.5235006 | L64: =ABS(Table2234210234[[#This Row],[RESyx]]) -> 1.5235006 | M64: =Table2234210234[[#This Row],[Y_pred]]*E$25+E$26 -> 11.790965 | N64: =Table2234210234[[#This Row],[X-Y]]^2 -> 7.7969408 | O64: =Table2234210234[[#This Row],[yest_rect]]-Table2234210234[[#This Row],[REF]] -> 1.7709649 | P64: =Table2234210234[[#This Row],[dif rec]]^2 -> 3.1363167 | Q64: =ABS(Table2234210234[[#This Row],[diff-bias]]) -> 2.022095 | R64: =CELL("row",Table2234210234[[#This Row],[Position]]) -> 64 | S64: =Table2234210234[[#This Row],[REF]]-D$13 -> -0.98999975 | T64: =ABS(Table2234210234[[#This Row],[lab-med]]) -> 0.98999975 | U64: =Table2234210234[[#This Row],[Y_pred]]-F$13 -> 1.0349631 | V64: =ABS(Table2234210234[[#This Row],[anl-med]]) -> 1.0349631 | W64: =Table2234210234[[#This Row],[lab-med]]*Table2234210234[[#This Row],[anl-med]] -> -1.0246132
B65: =VALUE((Table2234210234[[#This Row],[Column3]]-62)) -> 3 | C65: S003 | D65: 10 | F65: 8.7886583 | G65: =Table2234210234[[#This Row],[Y_pred]]-Table2234210234[[#This Row],[REF]] -> -1.2113417 | H65: =Table2234210234[[#This Row],[X-Y]]-E$20 -> -1.981547 | I65: =Table2234210234[[#This Row],[Y_pred]]-E$20 -> 8.018453 | J65: =Table2234210234[[#This Row],[Y_pred]]*E$21+E$22 -> 9.6710225 | K65: =Table2234210234[[#This Row],[Yest]]-Table2234210234[[#This Row],[REF]] -> -0.32897755 | L65: =ABS(Table2234210234[[#This Row],[RESyx]]) -> 0.32897755 | M65: =Table2234210234[[#This Row],[Y_pred]]*E$25+E$26 -> 8.8508127 | N65: =Table2234210234[[#This Row],[X-Y]]^2 -> 1.4673487 | O65: =Table2234210234[[#This Row],[yest_rect]]-Table2234210234[[#This Row],[REF]] -> -1.1491873 | P65: =Table2234210234[[#This Row],[dif rec]]^2 -> 1.3206314 | Q65: =ABS(Table2234210234[[#This Row],[diff-bias]]) -> 1.981547 | R65: =CELL("row",Table2234210234[[#This Row],[Position]]) -> 65 | S65: =Table2234210234[[#This Row],[REF]]-D$13 -> -1.0100003 | T65: =ABS(Table2234210234[[#This Row],[lab-med]]) -> 1.0100003 | U65: =Table2234210234[[#This Row],[Y_pred]]-F$13 -> -2.9886794 | V65: =ABS(Table2234210234[[#This Row],[anl-med]]) -> 2.9886794 | W65: =Table2234210234[[#This Row],[lab-med]]*Table2234210234[[#This Row],[anl-med]] -> 3.0185669
B66: =VALUE((Table2234210234[[#This Row],[Column3]]-62)) -> 4 | C66: S004 | D66: 10.5 | F66: 14.003733 | G66: =Table2234210234[[#This Row],[Y_pred]]-Table2234210234[[#This Row],[REF]] -> 3.5037329 | H66: =Table2234210234[[#This Row],[X-Y]]-E$20 -> 2.7335276 | I66: =Table2234210234[[#This Row],[Y_pred]]-E$20 -> 13.233528 | J66: =Table2234210234[[#This Row],[Y_pred]]*E$21+E$22 -> 12.097957 | K66: =Table2234210234[[#This Row],[Yest]]-Table2234210234[[#This Row],[REF]] -> 1.5979567 | L66: =ABS(Table2234210234[[#This Row],[RESyx]]) -> 1.5979567 | M66: =Table2234210234[[#This Row],[Y_pred]]*E$25+E$26 -> 12.661568 | N66: =Table2234210234[[#This Row],[X-Y]]^2 -> 12.276144 | O66: =Table2234210234[[#This Row],[yest_rect]]-Table2234210234[[#This Row],[REF]] -> 2.1615677 | P66: =Table2234210234[[#This Row],[dif rec]]^2 -> 4.6723747 | Q66: =ABS(Table2234210234[[#This Row],[diff-bias]]) -> 2.7335276 | R66: =CELL("row",Table2234210234[[#This Row],[Position]]) -> 66 | S66: =Table2234210234[[#This Row],[REF]]-D$13 -> -0.51000025 | T66: =ABS(Table2234210234[[#This Row],[lab-med]]) -> 0.51000025 | U66: =Table2234210234[[#This Row],[Y_pred]]-F$13 -> 2.2263952 | V66: =ABS(Table2234210234[[#This Row],[anl-med]]) -> 2.2263952 | W66: =Table2234210234[[#This Row],[lab-med]]*Table2234210234[[#This Row],[anl-med]] -> -1.1354621
B67: =VALUE((Table2234210234[[#This Row],[Column3]]-62)) -> 5 | C67: S005 | D67: 10.78 | F67: 9.9301256 | G67: =Table2234210234[[#This Row],[Y_pred]]-Table2234210234[[#This Row],[REF]] -> -0.84987407 | H67: =Table2234210234[[#This Row],[X-Y]]-E$20 -> -1.6200793 | I67: =Table2234210234[[#This Row],[Y_pred]]-E$20 -> 9.1599204 | J67: =Table2234210234[[#This Row],[Y_pred]]*E$21+E$22 -> 10.202226 | K67: =Table2234210234[[#This Row],[Yest]]-Table2234210234[[#This Row],[REF]] -> -0.5777737 | L67: =ABS(Table2234210234[[#This Row],[RESyx]]) -> 0.5777737 | M67: =Table2234210234[[#This Row],[Y_pred]]*E$25+E$26 -> 9.6849048 | N67: =Table2234210234[[#This Row],[X-Y]]^2 -> 0.72228594 | O67: =Table2234210234[[#This Row],[yest_rect]]-Table2234210234[[#This Row],[REF]] -> -1.0950949 | P67: =Table2234210234[[#This Row],[dif rec]]^2 -> 1.1992329 | Q67: =ABS(Table2234210234[[#This Row],[diff-bias]]) -> 1.6200793 | R67: =CELL("row",Table2234210234[[#This Row],[Position]]) -> 67 | S67: =Table2234210234[[#This Row],[REF]]-D$13 -> -0.23000055 | T67: =ABS(Table2234210234[[#This Row],[lab-med]]) -> 0.23000055 | U67: =Table2234210234[[#This Row],[Y_pred]]-F$13 -> -1.8472121 | V67: =ABS(Table2234210234[[#This Row],[anl-med]]) -> 1.8472121 | W67: =Table2234210234[[#This Row],[lab-med]]*Table2234210234[[#This Row],[anl-med]] -> 0.42485979
...

Sheet Lesnoff
W1: INSTRUCTIONS
C3: Lesnoff
C6: =CONCATENATE(D62," = f (",F62," )") -> REF = f (Lesnoff ) | H6: CALIBRATION INFORMATION
D7: =D62 -> REF | F7: =F62 -> Lesnoff | H7: N= | I7: 500 | X7: last point=
C8: N= | E8: =COUNT(Table22342102345[REF]) -> 80 | H8: SECV= | I8: 1.2 | X8: =62+E8 -> 142
C9: Average= | D9: =AVERAGE(Table22342102345[REF]) -> 11.1095 | F9: =AVERAGE(Table22342102345[Lesnoff]) -> 11.897242 | H9: Number of Terms = | J9: 12
C10: Min= | D10: =MIN(Table22342102345[REF]) -> 8.9700003 | E10: =ROUNDDOWN(MIN(D10,F10),0) -> 8 | F10: =MIN(Table22342102345[Lesnoff]) -> 9.4831672 | H10: Alpha= | I10: 0.05 | W10: =E10+E20 -> 8.787742
C11: Max= | D11: =MAX(Table22342102345[REF]) -> 14.43 | E11: =ROUNDUP(MAX(D11,F11),0)+1 -> 17 | F11: =MAX(Table22342102345[Lesnoff]) -> 15.822369 | H11: Tvalue= | I11: =TINV(I10,E8) -> 1.9900634 | W11: =E11+E20 -> 17.787742
C12: SD= | D12: =STDEV(Table22342102345[REF]) -> 1.172905 | F12: =STDEV(Table22342102345[Lesnoff]) -> 1.1398778 | H12: Fvalue= | I12: =FINV(I10,E8-1,I7-1-J9) -> 1.3057951
C13: Medians= | D13: =MEDIAN(Table22342102345[REF]) -> 11.01 | F13: =MEDIAN(Table22342102345[Lesnoff]) -> 11.800173
C14: SD_medians= | D14: =1.4826*(MEDIAN(Table22342102345[abs(lab)])) -> 1.4677736 | F14: =1.4826*MEDIAN(Table22342102345[abs(anl)]) -> 1.1583035
F15: Robust(medians)
C16: RMSEP= | E16: =SQRT(AVERAGE(Table22342102345[dif^2])) -> 1.0449743 | F16: =SQRT(F18^2+E20^2) -> 0.96051275
C17: Median ABS errors= | F17: =MEDIAN(Table22342102345[abs_errors]) -> 0.37069226
C18: SEPC= | E18: =STDEV(Table22342102345[X-Y]) -> 0.69094235 | F18: =1.4826*MEDIAN(Table22342102345[abs_errors]) -> 0.54958834 | H18: F_sep= | I18: =I8*I12 -> 1.5669542 | J18: =IF(E18>I18,"S"," ns ") -> ns | X18: Yrec | Y18: Xrec
C19: RSDyx= | E19: =STEYX(Table22342102345[REF],Table22342102345[Lesnoff]) -> 0.67244567 | F19: =1.4826*MEDIAN(Table22342102345[Abs_erroryx]) -> 0.48584972 | W19: y1rect= | X19: =E$26+E$25*E10 -> 7.0993382 | Y19: =E10 -> 8
C20: BIAS= | E20: =F9-D9 -> 0.78774196 | F20: =F13-D13 -> 0.7901732 | H20: Tobs_bias= | I20: =ABS(E20/(SQRT(SUM(Table22342102345[dif^2])/(E8*(E8-1))))) -> 6.7002642 | J20: =IF(I20>I11,"S","ns") -> S | W20: y2rect= | X20: =E$26+E$25*E11 -> 16.360107 | Y20: =E11 -> 17
C21: Slope= | E21: =SLOPE(Table22342102345[REF],Table22342102345[Lesnoff]) -> 0.84568227 | H21: Tobs_slope= | I21: =ABS(E21-1)*SQRT((E8-1)*F12^2/E19^2) -> 2.3250403 | J21: =IF(I21>I11,"S"," ns ") -> S | W21: ym= | X21: =E$26+E$25*F9 -> 11.1095 | Y21: =F9 -> 11.897242
C22: Intercept= | E22: =INTERCEPT(Table22342102345[REF],Table22342102345[Lesnoff]) -> 1.0482135
C23: RSQ= | E23: =RSQ(Table22342102345[REF],Table22342102345[Lesnoff]) -> 0.67546896 | F23: =(D12^2-F19^2)/D12^2 -> 0.82841542
C24: RPD= | E24: =1/SQRT(1-E23) -> 1.755383 | F24: =1/SQRT(1-F23) -> 2.4141312 | H24: RPD2= | I24: =D12/E19 -> 1.7442375
C25: Least rectangle slope= | E25: =(D12/F12) -> 1.0289743 | H25: Quartile75= | I25: =QUARTILE(Table22342102345[abs_errors],3) -> 0.77082167 | W25: cov(x,y)= | X25: =COVAR(Table22342102345[REF],Table22342102345[Lesnoff]) -> 1.0850779
C26: Least rectangle intercept= | E26: =D9-E25*F9 -> -1.1324562 | W26: sign(cov) | X26: =SIGN(X25) -> 1
C27: RMSEPrec= | E27: =SQRT(AVERAGE(Table22342102345[dif_rec^2])) -> 0.69569024
W29: min resid= | X29: =MIN(Table22342102345[X-Y]) -> -1.6852089 | Y29: =X29 -> -1.6852089
W30: max resid= | X30: =MAX(Table22342102345[X-Y]) -> 2.1042986 | Y30: =X30 -> 2.1042986
X38: last point=
X39: =X8 -> 142 | Y39: the last point must be changed in serie 1 for X and Y
Y40: click in the graph
Y41: select data
X58: last point=
W59: =W60*E8 -> 53.086124 | X59: =X39 -> 142
T60: =MEDIAN(Table22342102345[abs(lab)]) -> 0.98999975 | V60: =MEDIAN(Table22342102345[abs(anl)]) -> 0.78126498 | W60: =MEDIAN(Table22342102345[Produits Lab x Anl]) -> 0.66357655
D61: Y | F61: X
B62: Position | C62: SN | D62: REF | E62: Column1 | F62: Lesnoff | G62: X-Y | H62: diff-bias | I62: Xbiased | J62: Yest | K62: RESyx | L62: Abs_erroryx | M62: yest_rect | N62: dif^2 | O62: dif rec | P62: dif_rec^2 | Q62: abs_errors | R62: Column3 | S62: lab-med | T62: abs(lab) | U62: anl-med | V62: abs(anl) | W62: Produits Lab x Anl | X62: =D62 -> REF | AA62: =F62 -> Lesnoff
B63: =VALUE((Table22342102345[[#This Row],[Column3]]-62)) -> 1 | C63: S001 | D63: 9.9399996 | F63: 10.766817 | G63: =Table22342102345[[#This Row],[Lesnoff]]-Table22342102345[[#This Row],[REF]] -> 0.82681692 | H63: =Table22342102345[[#This Row],[X-Y]]-E$20 -> 0.039074967 | I63: =Table22342102345[[#This Row],[Lesnoff]]-E$20 -> 9.9790746 | J63: =Table22342102345[[#This Row],[Lesnoff]]*E$21+E$22 -> 10.153519 | K63: =Table22342102345[[#This Row],[Yest]]-Table22342102345[[#This Row],[REF]] -> 0.21351966 | L63: =ABS(Table22342102345[[#This Row],[RESyx]]) -> 0.21351966 | M63: =Table22342102345[[#This Row],[Lesnoff]]*E$25+E$26 -> 9.9463213 | N63: =Table22342102345[[#This Row],[X-Y]]^2 -> 0.68362623 | O63: =Table22342102345[[#This Row],[yest_rect]]-Table22342102345[[#This Row],[REF]] -> 0.0063216858 | P63: =Table22342102345[[#This Row],[dif rec]]^2 -> 3.9963711e-05 | Q63: =ABS(Table22342102345[[#This Row],[diff-bias]]) -> 0.039074967 | R63: =CELL("row",Table22342102345[[#This Row],[Position]]) -> 63 | S63: =Table22342102345[[#This Row],[REF]]-D$13 -> -1.0700007 | T63: =ABS(Table22342102345[[#This Row],[lab-med]]) -> 1.0700007 | U63: =Table22342102345[[#This Row],[Lesnoff]]-F$13 -> -1.0333569 | V63: =ABS(Table22342102345[[#This Row],[anl-med]]) -> 1.0333569 | W63: =Table22342102345[[#This Row],[lab-med]]*Table22342102345[[#This Row],[anl-med]] -> 1.1056926
B64: =VALUE((Table22342102345[[#This Row],[Column3]]-62)) -> 2 | C64: S002 | D64: 10.020001 | F64: 11.76008 | G64: =Table22342102345[[#This Row],[Lesnoff]]-Table22342102345[[#This Row],[REF]] -> 1.7400793 | H64: =Table22342102345[[#This Row],[X-Y]]-E$20 -> 0.95233733 | I64: =Table22342102345[[#This Row],[Lesnoff]]-E$20 -> 10.972338 | J64: =Table22342102345[[#This Row],[Lesnoff]]*E$21+E$22 -> 10.993504 | K64: =Table22342102345[[#This Row],[Yest]]-Table22342102345[[#This Row],[REF]] -> 0.97350388 | L64: =ABS(Table22342102345[[#This Row],[RESyx]]) -> 0.97350388 | M64: =Table22342102345[[#This Row],[Lesnoff]]*E$25+E$26 -> 10.968364 | N64: =Table22342102345[[#This Row],[X-Y]]^2 -> 3.0278759 | O64: =Table22342102345[[#This Row],[yest_rect]]-Table22342102345[[#This Row],[REF]] -> 0.94836315 | P64: =Table22342102345[[#This Row],[dif rec]]^2 -> 0.89939266 | Q64: =ABS(Table22342102345[[#This Row],[diff-bias]]) -> 0.95233733 | R64: =CELL("row",Table22342102345[[#This Row],[Position]]) -> 64 | S64: =Table22342102345[[#This Row],[REF]]-D$13 -> -0.98999975 | T64: =ABS(Table22342102345[[#This Row],[lab-med]]) -> 0.98999975 | U64: =Table22342102345[[#This Row],[Lesnoff]]-F$13 -> -0.040093669 | V64: =ABS(Table22342102345[[#This Row],[anl-med]]) -> 0.040093669 | W64: =Table22342102345[[#This Row],[lab-med]]*Table22342102345[[#This Row],[anl-med]] -> 0.039692722
B65: =VALUE((Table22342102345[[#This Row],[Column3]]-62)) -> 3 | C65: S003 | D65: 10 | F65: 10.747413 | G65: =Table22342102345[[#This Row],[Lesnoff]]-Table22342102345[[#This Row],[REF]] -> 0.74741279 | H65: =Table22342102345[[#This Row],[X-Y]]-E$20 -> -0.04032917 | I65: =Table22342102345[[#This Row],[Lesnoff]]-E$20 -> 9.9596708 | J65: =Table22342102345[[#This Row],[Lesnoff]]*E$21+E$22 -> 10.13711 | K65: =Table22342102345[[#This Row],[Yest]]-Table22342102345[[#This Row],[REF]] -> 0.13710986 | L65: =ABS(Table22342102345[[#This Row],[RESyx]]) -> 0.13710986 | M65: =Table22342102345[[#This Row],[Lesnoff]]*E$25+E$26 -> 9.9263553 | N65: =Table22342102345[[#This Row],[X-Y]]^2 -> 0.55862587 | O65: =Table22342102345[[#This Row],[yest_rect]]-Table22342102345[[#This Row],[REF]] -> -0.073644661 | P65: =Table22342102345[[#This Row],[dif rec]]^2 -> 0.0054235361 | Q65: =ABS(Table22342102345[[#This Row],[diff-bias]]) -> 0.04032917 | R65: =CELL("row",Table22342102345[[#This Row],[Position]]) -> 65 | S65: =Table22342102345[[#This Row],[REF]]-D$13 -> -1.0100003 | T65: =ABS(Table22342102345[[#This Row],[lab-med]]) -> 1.0100003 | U65: =Table22342102345[[#This Row],[Lesnoff]]-F$13 -> -1.0527607 | V65: =ABS(Table22342102345[[#This Row],[anl-med]]) -> 1.0527607 | W65: =Table22342102345[[#This Row],[lab-med]]*Table22342102345[[#This Row],[anl-med]] -> 1.0632885
B66: =VALUE((Table22342102345[[#This Row],[Column3]]-62)) -> 4 | C66: S004 | D66: 10.5 | F66: 12.206395 | G66: =Table22342102345[[#This Row],[Lesnoff]]-Table22342102345[[#This Row],[REF]] -> 1.7063949 | H66: =Table22342102345[[#This Row],[X-Y]]-E$20 -> 0.91865296 | I66: =Table22342102345[[#This Row],[Lesnoff]]-E$20 -> 11.418653 | J66: =Table22342102345[[#This Row],[Lesnoff]]*E$21+E$22 -> 11.370945 | K66: =Table22342102345[[#This Row],[Yest]]-Table22342102345[[#This Row],[REF]] -> 0.87094517 | L66: =ABS(Table22342102345[[#This Row],[RESyx]]) -> 0.87094517 | M66: =Table22342102345[[#This Row],[Lesnoff]]*E$25+E$26 -> 11.42761 | N66: =Table22342102345[[#This Row],[X-Y]]^2 -> 2.9117836 | O66: =Table22342102345[[#This Row],[yest_rect]]-Table22342102345[[#This Row],[REF]] -> 0.92761045 | P66: =Table22342102345[[#This Row],[dif rec]]^2 -> 0.86046114 | Q66: =ABS(Table22342102345[[#This Row],[diff-bias]]) -> 0.91865296 | R66: =CELL("row",Table22342102345[[#This Row],[Position]]) -> 66 | S66: =Table22342102345[[#This Row],[REF]]-D$13 -> -0.51000025 | T66: =ABS(Table22342102345[[#This Row],[lab-med]]) -> 0.51000025 | U66: =Table22342102345[[#This Row],[Lesnoff]]-F$13 -> 0.40622146 | V66: =ABS(Table22342102345[[#This Row],[anl-med]]) -> 0.40622146 | W66: =Table22342102345[[#This Row],[lab-med]]*Table22342102345[[#This Row],[anl-med]] -> -0.20717305
B67: =VALUE((Table22342102345[[#This Row],[Column3]]-62)) -> 5 | C67: S005 | D67: 10.78 | F67: 10.727669 | G67: =Table22342102345[[#This Row],[Lesnoff]]-Table22342102345[[#This Row],[REF]] -> -0.052330382 | H67: =Table22342102345[[#This Row],[X-Y]]-E$20 -> -0.84007234 | I67: =Table22342102345[[#This Row],[Lesnoff]]-E$20 -> 9.9399274 | J67: =Table22342102345[[#This Row],[Lesnoff]]*E$21+E$22 -> 10.120413 | K67: =Table22342102345[[#This Row],[Yest]]-Table22342102345[[#This Row],[REF]] -> -0.65958654 | L67: =ABS(Table22342102345[[#This Row],[RESyx]]) -> 0.65958654 | M67: =Table22342102345[[#This Row],[Lesnoff]]*E$25+E$26 -> 9.9060398 | N67: =Table22342102345[[#This Row],[X-Y]]^2 -> 0.0027384689 | O67: =Table22342102345[[#This Row],[yest_rect]]-Table22342102345[[#This Row],[REF]] -> -0.87395988 | P67: =Table22342102345[[#This Row],[dif rec]]^2 -> 0.76380588 | Q67: =ABS(Table22342102345[[#This Row],[diff-bias]]) -> 0.84007234 | R67: =CELL("row",Table22342102345[[#This Row],[Position]]) -> 67 | S67: =Table22342102345[[#This Row],[REF]]-D$13 -> -0.23000055 | T67: =ABS(Table22342102345[[#This Row],[lab-med]]) -> 0.23000055 | U67: =Table22342102345[[#This Row],[Lesnoff]]-F$13 -> -1.0725041 | V67: =ABS(Table22342102345[[#This Row],[anl-med]]) -> 1.0725041 | W67: =Table22342102345[[#This Row],[lab-med]]*Table22342102345[[#This Row],[anl-med]] -> 0.24667654
...

Sheet Roger
W1: INSTRUCTIONS
C3: Roger
C6: =CONCATENATE(D62," = f (",F62," )") -> REF = f (Roger ) | H6: CALIBRATION INFORMATION
D7: =D62 -> REF | F7: =F62 -> Roger | H7: N= | I7: 500 | X7: last point=
C8: N= | E8: =COUNT(Table223421023456[REF]) -> 80 | H8: SECV= | I8: 1.2 | X8: =62+E8 -> 142
C9: Average= | D9: =AVERAGE(Table223421023456[REF]) -> 11.1095 | F9: =AVERAGE(Table223421023456[Roger]) -> 11.661915 | H9: Number of Terms = | J9: 12
C10: Min= | D10: =MIN(Table223421023456[REF]) -> 8.9700003 | E10: =ROUNDDOWN(MIN(D10,F10),0) -> 6 | F10: =MIN(Table223421023456[Roger]) -> 6.8713 | H10: Alpha= | I10: 0.05 | W10: =E10+E20 -> 6.552415
C11: Max= | D11: =MAX(Table223421023456[REF]) -> 14.43 | E11: =ROUNDUP(MAX(D11,F11),0)+1 -> 18 | F11: =MAX(Table223421023456[Roger]) -> 16.427 | H11: Tvalue= | I11: =TINV(I10,E8) -> 1.9900634 | W11: =E11+E20 -> 18.552415
C12: SD= | D12: =STDEV(Table223421023456[REF]) -> 1.172905 | F12: =STDEV(Table223421023456[Roger]) -> 1.6914399 | H12: Fvalue= | I12: =FINV(I10,E8-1,I7-1-J9) -> 1.3057951
C13: Medians= | D13: =MEDIAN(Table223421023456[REF]) -> 11.01 | F13: =MEDIAN(Table223421023456[Roger]) -> 11.7815
C14: SD_medians= | D14: =1.4826*(MEDIAN(Table223421023456[abs(lab)])) -> 1.4677736 | F14: =1.4826*MEDIAN(Table223421023456[abs(anl)]) -> 1.7287116
F15: Robust(medians)
C16: RMSEP= | E16: =SQRT(AVERAGE(Table223421023456[dif^2])) -> 1.3544858 | F16: =SQRT(F18^2+E20^2) -> 1.6310157
C17: Median ABS errors= | F17: =MEDIAN(Table223421023456[abs_errors]) -> 1.0350851
C18: SEPC= | E18: =STDEV(Table223421023456[X-Y]) -> 1.2445199 | F18: =1.4826*MEDIAN(Table223421023456[abs_errors]) -> 1.5346172 | H18: F_sep= | I18: =I8*I12 -> 1.5669542 | J18: =IF(E18>I18,"S"," ns ") -> ns | X18: Yrec | Y18: Xrec
C19: RSDyx= | E19: =STEYX(Table223421023456[REF],Table223421023456[Roger]) -> 0.86830318 | F19: =1.4826*MEDIAN(Table223421023456[Abs_erroryx]) -> 0.90886953 | W19: y1rect= | X19: =E$26+E$25*E10 -> 7.1833253 | Y19: =E10 -> 6
C20: BIAS= | E20: =F9-D9 -> 0.55241502 | F20: =F13-D13 -> 0.77149975 | H20: Tobs_bias= | I20: =ABS(E20/(SQRT(SUM(Table223421023456[dif^2])/(E8*(E8-1))))) -> 3.6249712 | J20: =IF(I20>I11,"S","ns") -> S | W20: y2rect= | X20: =E$26+E$25*E11 -> 15.504555 | Y20: =E11 -> 18
C21: Slope= | E21: =SLOPE(Table223421023456[REF],Table223421023456[Roger]) -> 0.46974386 | H21: Tobs_slope= | I21: =ABS(E21-1)*SQRT((E8-1)*F12^2/E19^2) -> 9.1808823 | J21: =IF(I21>I11,"S"," ns ") -> S | W21: ym= | X21: =E$26+E$25*F9 -> 11.1095 | Y21: =F9 -> 11.661915
C22: Intercept= | E22: =INTERCEPT(Table223421023456[REF],Table223421023456[Roger]) -> 5.631387
C23: RSQ= | E23: =RSQ(Table223421023456[REF],Table223421023456[Roger]) -> 0.45889115 | F23: =(D12^2-F19^2)/D12^2 -> 0.3995492
C24: RPD= | E24: =1/SQRT(1-E23) -> 1.3594326 | F24: =1/SQRT(1-F23) -> 1.2905097 | H24: RPD2= | I24: =D12/E19 -> 1.3508012
C25: Least rectangle slope= | E25: =(D12/F12) -> 0.69343582 | H25: Quartile75= | I25: =QUARTILE(Table223421023456[abs_errors],3) -> 1.4340425 | W25: cov(x,y)= | X25: =COVAR(Table223421023456[REF],Table223421023456[Roger]) -> 1.3271235
C26: Least rectangle intercept= | E26: =D9-E25*F9 -> 3.0227104 | W26: sign(cov) | X26: =SIGN(X25) -> 1
C27: RMSEPrec= | E27: =SQRT(AVERAGE(Table223421023456[dif_rec^2])) -> 0.93619956
W29: min resid= | X29: =MIN(Table223421023456[X-Y]) -> -2.2086999 | Y29: =X29 -> -2.2086999
W30: max resid= | X30: =MAX(Table223421023456[X-Y]) -> 3.094 | Y30: =X30 -> 3.094
X38: last point=
X39: =X8 -> 142 | Y39: the last point must be changed in serie 1 for X and Y
Y40: click in the graph
Y41: select data
X58: last point=
W59: =W60*E8 -> 53.735862 | X59: =X39 -> 142
T60: =MEDIAN(Table223421023456[abs(lab)]) -> 0.98999975 | V60: =MEDIAN(Table223421023456[abs(anl)]) -> 1.166 | W60: =MEDIAN(Table223421023456[Produits Lab x Anl]) -> 0.67169828
D61: Y | F61: X
B62: Position | C62: SN | D62: REF | E62: Column1 | F62: Roger | G62: X-Y | H62: diff-bias | I62: Xbiased | J62: Yest | K62: RESyx | L62: Abs_erroryx | M62: yest_rect | N62: dif^2 | O62: dif rec | P62: dif_rec^2 | Q62: abs_errors | R62: Column3 | S62: lab-med | T62: abs(lab) | U62: anl-med | V62: abs(anl) | W62: Produits Lab x Anl | X62: =D62 -> REF | AA62: =F62 -> Roger
